ERROR: After October 2020 you may experience errors when installing or updating packages. This is because pip will change the way that it resolves dependency conflicts.

We recommend you use --use-feature=2020-resolver to test your packages with the new resolver before it becomes the default.

tensorboard 2.11.0 requires protobuf<4,>=3.9.2, but you'll have protobuf 4.21.2 which is incompatible.
huggingface-hub 0.11.0 requires packaging>=20.9, but you'll have packaging 20.4 which is incompatible.
ERROR: After October 2020 you may experience errors when installing or updating packages. This is because pip will change the way that it resolves dependency conflicts.

We recommend you use --use-feature=2020-resolver to test your packages with the new resolver before it becomes the default.

requests 2.24.0 requires urllib3!=1.25.0,!=1.25.1,<1.26,>=1.21.1, but you'll have urllib3 1.26.13 which is incompatible.
/cluster/apps/eb/software/Python/3.8.6-GCCcore-10.2.0/lib/python3.8/site-packages/requests/__init__.py:89: RequestsDependencyWarning: urllib3 (1.26.13) or chardet (3.0.4) doesn't match a supported version!
  warnings.warn("urllib3 ({}) or chardet ({}) doesn't match a supported "
wandb: Appending key for api.wandb.ai to your netrc file: /cluster/home/eivinkoh/.netrc
/cluster/apps/eb/software/Python/3.8.6-GCCcore-10.2.0/lib/python3.8/site-packages/requests/__init__.py:89: RequestsDependencyWarning: urllib3 (1.26.13) or chardet (3.0.4) doesn't match a supported version!
  warnings.warn("urllib3 ({}) or chardet ({}) doesn't match a supported "
/cluster/home/eivinkoh/.local/lib/python3.8/site-packages/torch/distributed/launch.py:180: FutureWarning: The module torch.distributed.launch is deprecated
and will be removed in future. Use torchrun.
Note that --use_env is set by default in torchrun.
If your script expects `--local_rank` argument to be set, please
change it to read from `os.environ['LOCAL_RANK']` instead. See 
https://pytorch.org/docs/stable/distributed.html#launch-utility for 
further instructions

  warnings.warn(
WARNING:torch.distributed.run:
*****************************************
Setting OMP_NUM_THREADS environment variable for each process to be 1 in default, to avoid your system being overloaded, please further tune the variable for optimal performance in your application as needed. 
*****************************************
Traceback (most recent call last):
Traceback (most recent call last):
Traceback (most recent call last):
  File "train.py", line 21, in <module>
  File "train.py", line 21, in <module>
  File "train.py", line 21, in <module>
Traceback (most recent call last):
  File "train.py", line 21, in <module>
            from torch.utils.tensorboard import SummaryWriterfrom torch.utils.tensorboard import SummaryWriterfrom torch.utils.tensorboard import SummaryWriter


  File "/cluster/home/eivinkoh/.local/lib/python3.8/site-packages/torch/utils/tensorboard/__init__.py", line 12, in <module>
  File "/cluster/home/eivinkoh/.local/lib/python3.8/site-packages/torch/utils/tensorboard/__init__.py", line 12, in <module>
  File "/cluster/home/eivinkoh/.local/lib/python3.8/site-packages/torch/utils/tensorboard/__init__.py", line 12, in <module>
    from torch.utils.tensorboard import SummaryWriter
  File "/cluster/home/eivinkoh/.local/lib/python3.8/site-packages/torch/utils/tensorboard/__init__.py", line 12, in <module>
            from .writer import FileWriter, SummaryWriter  # noqa: F401from .writer import FileWriter, SummaryWriter  # noqa: F401from .writer import FileWriter, SummaryWriter  # noqa: F401


  File "/cluster/home/eivinkoh/.local/lib/python3.8/site-packages/torch/utils/tensorboard/writer.py", line 9, in <module>
  File "/cluster/home/eivinkoh/.local/lib/python3.8/site-packages/torch/utils/tensorboard/writer.py", line 9, in <module>
  File "/cluster/home/eivinkoh/.local/lib/python3.8/site-packages/torch/utils/tensorboard/writer.py", line 9, in <module>
    from .writer import FileWriter, SummaryWriter  # noqa: F401
  File "/cluster/home/eivinkoh/.local/lib/python3.8/site-packages/torch/utils/tensorboard/writer.py", line 9, in <module>
        from tensorboard.compat.proto.event_pb2 import SessionLog    from tensorboard.compat.proto.event_pb2 import SessionLog
from tensorboard.compat.proto.event_pb2 import SessionLog
  File "/cluster/home/eivinkoh/.local/lib/python3.8/site-packages/tensorboard/compat/proto/event_pb2.py", line 17, in <module>

  File "/cluster/home/eivinkoh/.local/lib/python3.8/site-packages/tensorboard/compat/proto/event_pb2.py", line 17, in <module>
  File "/cluster/home/eivinkoh/.local/lib/python3.8/site-packages/tensorboard/compat/proto/event_pb2.py", line 17, in <module>
    from tensorboard.compat.proto.event_pb2 import SessionLog
  File "/cluster/home/eivinkoh/.local/lib/python3.8/site-packages/tensorboard/compat/proto/event_pb2.py", line 17, in <module>
            from tensorboard.compat.proto import summary_pb2 as tensorboard_dot_compat_dot_proto_dot_summary__pb2from tensorboard.compat.proto import summary_pb2 as tensorboard_dot_compat_dot_proto_dot_summary__pb2from tensorboard.compat.proto import summary_pb2 as tensorboard_dot_compat_dot_proto_dot_summary__pb2


  File "/cluster/home/eivinkoh/.local/lib/python3.8/site-packages/tensorboard/compat/proto/summary_pb2.py", line 17, in <module>
  File "/cluster/home/eivinkoh/.local/lib/python3.8/site-packages/tensorboard/compat/proto/summary_pb2.py", line 17, in <module>
      File "/cluster/home/eivinkoh/.local/lib/python3.8/site-packages/tensorboard/compat/proto/summary_pb2.py", line 17, in <module>
from tensorboard.compat.proto import summary_pb2 as tensorboard_dot_compat_dot_proto_dot_summary__pb2
  File "/cluster/home/eivinkoh/.local/lib/python3.8/site-packages/tensorboard/compat/proto/summary_pb2.py", line 17, in <module>
            from tensorboard.compat.proto import histogram_pb2 as tensorboard_dot_compat_dot_proto_dot_histogram__pb2from tensorboard.compat.proto import histogram_pb2 as tensorboard_dot_compat_dot_proto_dot_histogram__pb2from tensorboard.compat.proto import histogram_pb2 as tensorboard_dot_compat_dot_proto_dot_histogram__pb2


  File "/cluster/home/eivinkoh/.local/lib/python3.8/site-packages/tensorboard/compat/proto/histogram_pb2.py", line 36, in <module>
  File "/cluster/home/eivinkoh/.local/lib/python3.8/site-packages/tensorboard/compat/proto/histogram_pb2.py", line 36, in <module>
  File "/cluster/home/eivinkoh/.local/lib/python3.8/site-packages/tensorboard/compat/proto/histogram_pb2.py", line 36, in <module>
    from tensorboard.compat.proto import histogram_pb2 as tensorboard_dot_compat_dot_proto_dot_histogram__pb2
  File "/cluster/home/eivinkoh/.local/lib/python3.8/site-packages/tensorboard/compat/proto/histogram_pb2.py", line 36, in <module>
        _descriptor.FieldDescriptor(    _descriptor.FieldDescriptor(
_descriptor.FieldDescriptor(
  File "/cluster/home/eivinkoh/.local/lib/python3.8/site-packages/google/protobuf/descriptor.py", line 560, in __new__

  File "/cluster/home/eivinkoh/.local/lib/python3.8/site-packages/google/protobuf/descriptor.py", line 560, in __new__
  File "/cluster/home/eivinkoh/.local/lib/python3.8/site-packages/google/protobuf/descriptor.py", line 560, in __new__
    _descriptor.FieldDescriptor(
  File "/cluster/home/eivinkoh/.local/lib/python3.8/site-packages/google/protobuf/descriptor.py", line 560, in __new__
            _message.Message._CheckCalledFromGeneratedFile()_message.Message._CheckCalledFromGeneratedFile()_message.Message._CheckCalledFromGeneratedFile()


TypeError    TypeErrorTypeError: _message.Message._CheckCalledFromGeneratedFile(): : Descriptors cannot not be created directly.
If this call came from a _pb2.py file, your generated code is out of date and must be regenerated with protoc >= 3.19.0.
If you cannot immediately regenerate your protos, some other possible workarounds are:
 1. Downgrade the protobuf package to 3.20.x or lower.
 2. Set PROTOCOL_BUFFERS_PYTHON_IMPLEMENTATION=python (but this will use pure-Python parsing and will be much slower).

More information: https://developers.google.com/protocol-buffers/docs/news/2022-05-06#python-updates
Descriptors cannot not be created directly.
If this call came from a _pb2.py file, your generated code is out of date and must be regenerated with protoc >= 3.19.0.
If you cannot immediately regenerate your protos, some other possible workarounds are:
 1. Downgrade the protobuf package to 3.20.x or lower.
 2. Set PROTOCOL_BUFFERS_PYTHON_IMPLEMENTATION=python (but this will use pure-Python parsing and will be much slower).

More information: https://developers.google.com/protocol-buffers/docs/news/2022-05-06#python-updatesDescriptors cannot not be created directly.
If this call came from a _pb2.py file, your generated code is out of date and must be regenerated with protoc >= 3.19.0.
If you cannot immediately regenerate your protos, some other possible workarounds are:
 1. Downgrade the protobuf package to 3.20.x or lower.
 2. Set PROTOCOL_BUFFERS_PYTHON_IMPLEMENTATION=python (but this will use pure-Python parsing and will be much slower).

More information: https://developers.google.com/protocol-buffers/docs/news/2022-05-06#python-updates
TypeError

: Descriptors cannot not be created directly.
If this call came from a _pb2.py file, your generated code is out of date and must be regenerated with protoc >= 3.19.0.
If you cannot immediately regenerate your protos, some other possible workarounds are:
 1. Downgrade the protobuf package to 3.20.x or lower.
 2. Set PROTOCOL_BUFFERS_PYTHON_IMPLEMENTATION=python (but this will use pure-Python parsing and will be much slower).

More information: https://developers.google.com/protocol-buffers/docs/news/2022-05-06#python-updates
ERROR:torch.distributed.elastic.multiprocessing.api:failed (exitcode: 1) local_rank: 0 (pid: 1863800) of binary: /cluster/apps/eb/software/Python/3.8.6-GCCcore-10.2.0/bin/python3
Traceback (most recent call last):
  File "/cluster/apps/eb/software/Python/3.8.6-GCCcore-10.2.0/lib/python3.8/runpy.py", line 194, in _run_module_as_main
    return _run_code(code, main_globals, None,
  File "/cluster/apps/eb/software/Python/3.8.6-GCCcore-10.2.0/lib/python3.8/runpy.py", line 87, in _run_code
    exec(code, run_globals)
  File "/cluster/home/eivinkoh/.local/lib/python3.8/site-packages/torch/distributed/launch.py", line 195, in <module>
    main()
  File "/cluster/home/eivinkoh/.local/lib/python3.8/site-packages/torch/distributed/launch.py", line 191, in main
    launch(args)
  File "/cluster/home/eivinkoh/.local/lib/python3.8/site-packages/torch/distributed/launch.py", line 176, in launch
    run(args)
  File "/cluster/home/eivinkoh/.local/lib/python3.8/site-packages/torch/distributed/run.py", line 753, in run
    elastic_launch(
  File "/cluster/home/eivinkoh/.local/lib/python3.8/site-packages/torch/distributed/launcher/api.py", line 132, in __call__
    return launch_agent(self._config, self._entrypoint, list(args))
  File "/cluster/home/eivinkoh/.local/lib/python3.8/site-packages/torch/distributed/launcher/api.py", line 246, in launch_agent
    raise ChildFailedError(
torch.distributed.elastic.multiprocessing.errors.ChildFailedError: 
============================================================
train.py FAILED
------------------------------------------------------------
Failures:
[1]:
  time      : 2022-11-24_00:30:10
  host      : idun-04-01
  rank      : 1 (local_rank: 1)
  exitcode  : 1 (pid: 1863801)
  error_file: <N/A>
  traceback : To enable traceback see: https://pytorch.org/docs/stable/elastic/errors.html
[2]:
  time      : 2022-11-24_00:30:10
  host      : idun-04-01
  rank      : 2 (local_rank: 2)
  exitcode  : 1 (pid: 1863802)
  error_file: <N/A>
  traceback : To enable traceback see: https://pytorch.org/docs/stable/elastic/errors.html
[3]:
  time      : 2022-11-24_00:30:10
  host      : idun-04-01
  rank      : 3 (local_rank: 3)
  exitcode  : 1 (pid: 1863803)
  error_file: <N/A>
  traceback : To enable traceback see: https://pytorch.org/docs/stable/elastic/errors.html
------------------------------------------------------------
Root Cause (first observed failure):
[0]:
  time      : 2022-11-24_00:30:10
  host      : idun-04-01
  rank      : 0 (local_rank: 0)
  exitcode  : 1 (pid: 1863800)
  error_file: <N/A>
  traceback : To enable traceback see: https://pytorch.org/docs/stable/elastic/errors.html
============================================================
